Workbook
Name Manufacturer: '12-VLook'!$D$2:$D$2870
Name CommunicationType: '12-VLook'!$A$2:$A$2870
Name CorphostingDeviceTypeLookup: '12-VLook'!$N$2:$N$2870
Name Protocol: '12-VLook'!$B$2:$B$2050
Name DeviceTypesWithFirmware: '12-VLook'!$O$2:$O$2050
Name FloorNumber: '12-VLook'!$K$2:$K$2050
Name DeviceName: '12-VLook'!$P$2:$P$2870
Name ModelFromLBAM: '12-VLook'!$F$2:$F$2050
Name DeviceRiskLevel: '12-VLook'!$H$2:$H$2050
Name NetworkSwitchManufacturer: '12-VLook'!$M$2:$M$2050
Name System: '12-VLook'!$C$2:$C$2050
Name ManufacturerFromLBAM: '12-VLook'!$E$2:$E$2870
Name SwitchType: '12-VLook'!$G$2:$G$2050
Name QualifiedApproved: '12-VLook'!$I$2:$I$2050
Name NetworkSpeed: '12-VLook'!$L$2:$L$2050
Name AssetTypeAbbreviation: '12-VLook'!$J$2:$J$2870

Sheet Version Control
B2: Version Control and Governance
B4: Document Instructions
B5: Refer Instructions tab
B7: Revision History
B9: Revision Date | C9: Version | D9: Revised By | E9: Description of Changes
B10: 45119 | C10: 2 | D10: npert@ | E10: Added an option for N/A for serial relationships in the dropdown
B11: 45118 | C11: 2 | D11: npert@ | E11: b/290725624. device status column added to control panel and private network switch tabs (retired / active ) so they can be retired in LBAM
B12: 45106 | C12: 2 | D12: npert@ | E12: The total number of shares to the VLook sheet reached its maximum. A copy of the sheet has been made and the import on the VLook tab updated to conect to the new url
B13: 45098 | C13: 2 | D13: npert@ | E13: Updated field validation as per this doc for LBAM bulk upoad requirements
B14: 45078 | C14: 2 | D14: alanjackson@ | E14: Updated sheet with new menu item for Add-Ons, including a sub-menu for the ability to generate new GUIDs for one or many cells to support QR code payload asset.guid information
B15: 45044 | C15: 2 | D15: npert@ | E15: Added help text to column "Device ID & Any Other Information" to include examples of other IDs that can be stored
B16: 45030 | C16: 2 | D16: npert@ | E16: MUD File columns deleted from Tab3 (b/275347101)
B17: 45020 | C17: 2 | D17: alanjackson@ | E17: Default hide the columns related to IP Peer - Peer Comms (b/272695271) Add conditional formatting to highlight use of vague systems (b/252788003) Added asset function validation against LBAM table (b/276901321) Added Device Connection Type (b/235549300)
B18: 44994 | C18: 2 | D18: npert@ | E18: Column renamed to "Jack Label" (March 2021) Temporary device tab added (June 2021) Corphosting column added to identify corphosting status of each asset (Feb 2022) Device Owner Added (as requested by Caiti Banks Sept 2022) Serial Relationship column added Sept 2023 b/254291005) POE drop down Added (b/256110818) [UPoE+ added dropdown by approval ONLY)
B19: 44134 | C19: 2 | D19: npert@ nsass@ | E19: Merging of DBRS Audit and Appendix 6 V1.4 with fields reviewed and agreed during the Rews Enriched data for LBAM works Stronger validation of data entry (using data validation and conditional formatting) Addition of a Temporary Devices Tab to track both temporary commissioning devices and interim MDF/IDF monitoring systems Link between Tabs 3 and 4 reduced to be just Manufacturer and Model (removing the firmware) as firmware was defined as an equipment level attribute during LBAM data review Addition of a CorpHosted Field to track whether a device needed corphosting Addition of a Corphosting tab to assist in the corphosting process (still required copying and pasting into EFIM template) Generation of GUID directly in the sheet Auto creation of QR code payload Update to Instructions Script for menu item to autohide sheets depending on use (NC/Audit) Script to only offer devices for selected manufacturer
B20: 43810 | C20: 1.4 | D20: nsass@ | E20: Restructuring and Streamlining columns Alignment with DBRS Workbook for Service Now Upload Addition of Instructions Addition of Validations as per SSOT document Addition of Data Ownership
B23: Reviewer Table
B24: Name | C24: Date | D24: LGTM | E24: Comments
B25: Maryam Ahmad | D25: PENDING
B26: Jean-baptiste Marigo | D26: PENDING
B27: Richard Reid | C27: 45099 | D27: REVIEWED | E27: VaANANTAus comments to be addressed - resolved as of 29/07/2023
B28: Christopher May | C28: 45072 | D28: REVIEWED
B29: Avdoot Venkateswaran | D29: PENDING
B30: Thang Nguyen | C30: 45084 | D30: REVIEWED
B31: Clare Meredith | C31: 45058 | D31: REVIEWED
B32: Caiti Banks | C32: 45070 | D32: WAITING | E32: Approved, aware of all changes, new requirements reviewed and submitted 5/24
B33: Joe Benn | D33: PENDING
B34: Kyle Hasegawa | D34: PENDING
B35: Jason McElroy | D35: PENDING
B36: Natalie Skvortsova | D36: PENDING
B37: Trevor Pering | D37: PENDING
B38: Francesco Anselmo | D38: PENDING
B39: Samuel King | D39: PENDING
B40: Sohaib Sheikh | C40: 45103 | D40: REVIEWED
B41: Kaloyan Kaloyanov | C41: 45099 | D41: REVIEWED
B42: Ian McGrath | D42: PENDING
B43: Patrick Nehls | D43: PENDING
B44: Sean Mcnulty | D44: PENDING
B46: Approver Table
B47: Name | C47: Date | D47: LGTM | E47: Comments
...

Sheet Project Level Change Control
A1: Project Level Change Control
A3: Revision History
A5: Revision Date | B5: Version | C5: Revised By | D5: LDAP | E5: Description of Changes

Sheet Instructions
A1: Instruction for Appendix 6 - Digital Building Device Register
A3: General Guidance
A4: No. | B4: Description
A5: 1 | B5: The Appendix 6 - Digital Building Device Register is a critical aspect of project delivery and acts as a central data repository for all building systems data. It is to be used for corphosting/enrolling all IP devices onto the GEN network and also to upload all record data (IP and serial) to an asset database used by Google.
A6: 2 | B6: Create a copy of this template and use it for your specific project / audit with correct building code.
A7: 3 | B7: This sheet should be centrally managed by a single entity. For new construction / upgrade projects: Compliant - Design - MEP designer - Construction - General Contractor or Variable PM for India Smart Ready - Design - DBC - Construction - MSI For DBRS audits: - Surveyor conducting the audit
A8: 4 | B8: For new construction / upgrade projects: All device parameters of every device must be provided to Google at least 4-6 weeks (subject to project size) pANANTAr to the installation and commissioning on site.
A9: 5 | B9: The data populated by the System Owners / Surveyors should not have any obvious gaps or issues.
A10: 6 | B10: There should be no entries like ‘unknown’ or ‘N/A’ for fields that are expected. For a ‘unknown’ or ‘N/A’ response, provide a justification for that row item in the comments column in its respective tab.
A11: 7 | B11: There are many validation checks incorporated with cells as follows: - All cells that are mandatory to be filled are in "Yellow". Once these are filled, they would turn "White". If the entry is Not Applicable the N/A should be entered. If information for the entry could not be found then "Not Verified" should be entered. - Certain columns should not have duplicates. If there is a duplication error, the cell will highlight in "Red". - Certain cells will only take input in a certain format and will show an error message if not in the correct format such as IP address, Subnet Mask, Default Gateway, MAC address. - Cells with a dropdown should only be filled with items selectable from the list provided. - The QR Payload is automatically generated based on the information entered in other cells - The hostname is automatically generated based on the information entered in other cells - Device Type is automatically generated based on the manufacturer and model entered in the corresponding columns - Photos column will only accept URL's, N/A, or Not verified. - Datasheets and Technical manuals columns will only accept URL's, N/A, or Not verified. All datasheets should be stored on Google Drive and not a link to an external web site that is liable to change
A12: 8 | B12: A consistent format should be used throughout this device register: - A consistent font and size of text to be used - Data fields should be consistent across all cells (columns and rows)
A13: 9 | B13: On cells with dropdown, select the information as per the project / audit. In some extreme cases, the dropdowns might not show the specific information, if so, overwrite the cell with correct information and justify in the comments section.
A14: 10 | B14: When copying and pasting into this document from any source (internal or external), - Right click on the cell - Select Paste Special dropdown option - Select Paste values only (Ctrl, Shift, V) Do not use Ctrl & V as this will override any validation rules which may disrupt the sheet.
A16: Specific Guidance
A17: No. | B17: Description
A18: Project Level Change Control
A19: 1 | B19: This Tab is provided for Change Control to ensure changes made within the document are recorded
A20: 2 | B20: As a minimum the following changes should be recorded: • Issue from MSI/DBC/GC to SME/GEN Deploy for device provisioning • When Updated by SME with Provisioining information issued by Corphosting Team • Any changes of MAC address after devices provisioned that require GUTS ticket to change them • Final submission for import into SAP after PC
A21: 3 | B21: The revision date has to be recorded The revision version must be incremented The person making the change and their LDAP must be recorded In the comments a full description of the changes between the versions needs to be recorded
A23: Specific Guidance
A24: No. | B24: Description
A25: 1-Facility Questionnaire for DBRS Audits
A26: 1 | B26: This tab will be hidden from new build projects and only shown for audits.
A27: 2 | B27: To be filled out by the FM pANANTAr to Audits being carried out
A29: Tab 2 - Building
A30: 1 | B30: The Building Tab is used to capture broad building and system level information. The tab is structured in sections relating to different systems, for example BMS, LCS, EMS etc to be populated by individual Systems Owner / Surveyor
A31: =A30+1 -> 2 | B31: Row 3-23 General question about the building which should be available with: For New Construction - REWS PM and Local/Embedded PM For DBRS Audit - Surveyor POC to verify from Local FM
A32: =A31+1 -> 3 | B32: Row 25-27 General question about the Landlord which should be available with: For New Construction - REWS PM and Local/Embedded PM. PM to liaise with Landlord to obtain the information. For DBRS Audit -Surveyor POC to verify from Local FM
A33: =A32+1 -> 4 | B33: Row 29-35 General question about the FM which should be available with: For New Construction - Local FM on the project For DBRS Audit - Local FM in the building
A34: =A33+1 -> 5 | B34: Row 37-38 General question about the MDF/IDF Information which should be available with: For New Construction - GEN Deploy TPM on the project For DBRS Audit - Surveyor POC to verify from Local FM/GEN
A35: =A34+1 -> 6 | B35: Row 40-41 General question about the OT / Private Network Information which should be available with: For New Construction - System Owner on the project For DBRS Audit - Surveyor to obtain the data through the audit
A36: =A35+1 -> 7 | B36: Row 43 - 76 General question about the BMS installed in the building(s). Note: If the system does not apply to the project / audit, fill with N/A.
A37: =A36+1 -> 8 | B37: Row 78 - 110 General question about the LCS installed in the building(s). Note: If the system does not apply to the project / audit, fill with N/A.
A38: =A37+1 -> 9 | B38: Row 112 - 144 General question about the EMS installed in the building(s). Note: If the system does not apply to the project / audit, fill with N/A.
A39: =A38+1 -> 10 | B39: Row 146 - 178 General question about the Lift/Elevator installed in the building(s). Note: If the system does not apply to the project / audit, fill with N/A.
A40: =A39+1 -> 11 | B40: Row 180 - 212 General question about the Fire Alarm System installed in the building(s). Note: If the system does not apply to the project / audit, fill with N/A.
A41: =A40+1 -> 12 | B41: Row 214 - 246 General question about the Blinds/Drapes installed in the building(s). Note: If the system does not apply to the project / audit, fill with N/A.
A42: =A41+1 -> 13 | B42: Row 248 - 282 General question about the Google Food installed in the building(s). Note: If the system does not apply to the project / audit, fill with N/A.
... A45: =A44+1 -> 16 | B45: Row 350 - 384 General question about the Misc. System 3 installed in the building(s). Note: If the system does not apply to the project / audit, fill with N/A.
A46: Tab 3 - Devices Types
...

Sheet 1-Facility Questionnaire
A1: FACILITY QUESTIONNAIRE
A2: Building Information
A3: Site Code | B3: IN-BLR-ANANTA
A4: Survey Date | B4: 36892
A5: Surveyor
A6: Is the building accessable
A7: RTO Status
A8: Local Vendor/Supplier Information
A9: Category | B9: Vendor/Supplier Company Name | C9: Contact Name | D9: Contact Email (include LDAP where applicable ) | E9: Contact Phone | F9: Confirmed Attendance & Access for Survey | G9: Additional Comments
A10: BMS (Building Management System)
A11: LCS (Lighting Control System)
A12: EMS (Emergency Management System)
A13: Lift
A14: Food
A15: Fire Alarm
A16: Fire Alarm
A17: Mechanical
A18: Mechanical
A19: Electrical
A21: Blinds/Curtains
A22: Other-Specify
... A27: High-Level Information (Optional)
A28: Description | B28: Quantity (If Known) | C28: Connected to BMS? | D28: Comments
A29: Number of Chillers
A30: Number of Boilers
A31: Number of Air Handling Units (AHUs)
A32: Number of Fan Coil Units (FCUs)
A33: Number of UPS
A34: Is there a BMS system in this building? If yes, does it feed any other buildings? If not, where is it located?
A35: Planned Works (that include BOS related elememts , network connections , IP devices etc)
A36: System | B36: Planned Works? | C36: Description and location of Works | D36: Planned Start Date | E36: Planned End Date | F36: PANANTArity | G36: Comments and contacts regarding works
A37: Please Specify
A38: Please Specify
A39: Please Specify
A40: Please Specify
A41: Are there any other site/OT considerations you think the team need to be aware of
A42: Further Comments
A43: Insert Any Further Comments Here
A44: Access Requirements
A45: Health & Safety and Site Access | B45: Response | C45: Comments
...

Sheet 2-Building
A1: Questions | B1: Response by | C1: Comments
A2: Building Information | B2: PM (for New Construction) FM (for Existing Buildings) | C2: Comments
A3: Link to Project Site
A4: Building ID/Code | B4: IN-BLR-ANANTA
A5: Building Address
A6: Ownership Type | B6: Leased
A7: Lease Expiry Date
A8: Would you consider this a Strategic Building for Google? | B8: Yes
A9: Model of the building | B9: Model 1
A10: Cyber Compliant or Smart Ready? | B10: Smart Ready
A11: IoT Lite, IoT Hybrid or IoT Heavy? | B11: IoT Heavy
A12: Headcount in the building
A13: Google occupied % in the building | B13: 1
A14: Building Size in SQFT
A15: Total number of floors in the building | B15: 16 | C15: 3 Basements + GF + 11 Floors + Roof
A16: Number of floors occupied by Google | B16: 16
A17: Basement Included? | B17: Yes
A18: Roof Included? | B18: Yes
A19: Does Google Facilities manage the Systems on Google Floors? | B19: Yes
A20: Does Google Facilities manage the Building Main Plant and Common Areas? | B20: Yes
A21: Any Critical System Issues? Please describe. | B21: No
A22: High Priority System Alarms? Please describe. | B22: N/A | C22: Alarms are configured as per Appendix-1
A23: Any proposed changes to the building, additional phases or retrofits in the next year? | B23: No
A24: Landlord Information | B24: PM (for New Construction) FM (for Existing Buildings) | C24: Comments
A25: Who operates the Building Main Plant and Common Areas?
A26: Landlord Relationship | B26: Positive
A27: Name(s) the Administrator(s), (Building Engineer, Landlord, FM, etc)
A28: FM Information | B28: Response by FM | C28: Comments
A29: Lead FM name & LLDAP
A30: On-Site Technical FM Name & LLDAP
A31: On-Site Technical Expertise
A32: Are keys available to BMS, LCS, EMS, and any other panels?
A33: Does FM have a system for managing Panel Keys?
A34: Are passwords available to BMS, LCS, EMS, and/or any other system front ends?
A35: Does FM have a system for managing passwords?
A36: MDF/IDF Information | B36: Response by GEN | C36: Comments
A37: Number of MDFs, IDFS and Razors in the Building?
A38: Annotated floorplans showing Locations of MDFs, IDFS and Razors?
A39: OT / Private Network Information | B39: Response by System Contractor | C39: Comments
A40: Are there any Private / OT Networks onsite? If yes, provide details and record network devices in the Private Network Equipment tab.
...

Sheet 3-Devices Types
B1: Device Types | J1: Device Types | R1: Comments | S1: Risk & Remediation
A2: To be filled by: | B2: System Owner | J2: System Owner | L2: DBC (Design), MSI (Construction) for Smart Ready / MEP (Design), GC (Construction) for Cyber Compliant | S2: SME
A3: Notes | B3: Select the Device lookup from the dropdown to auto populate columns C to J. This will fill in the information as filled in Tab 4-All IP Devices (Format: Device Manufacturer-Device Model-Firmware Version ) | C3: AUTO POPULATED (DO NOT EDIT THIS FIELD) | D3: AUTO POPULATED (DO NOT EDIT THIS FIELD) | E3: AUTO POPULATED (DO NOT EDIT THIS FIELD) | F3: AUTO POPULATED (DO NOT EDIT THIS FIELD) | G3: Specify the manufacturers part number for the device, this should be available from the datasheet / part number list. (e.g. 80054180) | H3: Specify the communication speed of the device (e.g. 100MB/1G/10G full/half duplex) | I3: Specify if there is a requirement for a license for the devices and documents the details along with a screenshot (e.g. Controls Software Licensing Details) | J3: Provide link to the datasheet on Google Drive. (Coordinate with REWS PM for the folder location and access) (e.g. Link to Datasheet) | K3: Provide link to the user and technical manuals on Google Drive (Coordinate with REWS PM for the folder location and access) (e.g. Link to User / Technical Manual) | L3: Specify all the inbound protocols, source port, and the source required by the device. (e.g. UDP, 47808, Controller) | M3: Specify all the outbound protocols, destination ports, and destinations used by the device (e.g. TCP, 433, mqtt.google.com) | N3: Specify if any services have been currently enabled on the firmware for the project (e.g. SMTP/25) | O3: Specify if any services have been currently disabled on the firmware for the project (e.g. Telnet/23) | P3: Specify if the device has encountered any issues during commissioning. (e.g. The device uses proprietary protocols or device version has been superseded by a new revision) | Q3: Specify if there is any resolution plan for the known issues by the manufacturer. (E.g. The known issue will be captured under the manufacturers roadmap i.e. NTP will be available in Q3) | R3: Provide any comments if applicable. | S3: Specify the device risk level based on the criteria provided
A4: No. | B4: Device Type Lookup | C4: System | D4: Device / Asset Manufacturer | E4: Device / Asset Model (manufacturer) | F4: =Concatenate("Quantity (", Sum(F5:F101), ")") -> Quantity (3244) | G4: Manufacturer Part Number | H4: Communication Speed (10/100/1G) | I4: License Info | J4: Technical Data Sheet | K4: User / Technical Manuals | L4: Inbound Protocol, Source Port & Source | M4: Outbound Protocol, Destination Port & Destination | N4: Which services are currently enabled & port number on Firmware | O4: Which services are currently disabled & port number on Firmware | P4: Known issues | Q4: Known Issue Resolution | R4: Comments | S4: Device Risk level
A5: 1 | B5: ALC-G5CE | C5: {=iferror(index('4-All Devices'!$A:$BB, match($B5 ,'4-All Devices'!BG:BG,0 ),match(C$4,'4-All Devices'!$4:$4,0)),"")} -> Building Management System | D5: {=iferror(index('4-All Devices'!$A:$BB, match($B5 ,'4-All Devices'!BG:BG,0 ),match(D$4,'4-All Devices'!$4:$4,0)),"")} -> ALC | E5: {=iferror(index('4-All Devices'!$A:$BB, match($B5 ,'4-All Devices'!BG:BG,0 ),match(E$4,'4-All Devices'!$4:$4,0)),"")} -> G5CE | F5: =if(countifs('4-All Devices'!BG:BG,B5)=0,"",countifs('4-All Devices'!BG:BG,B5)) -> 151 | G5: G5CE | H5: 10/100 Mb Half/Full Duplex
A6: =A5+1 -> 2 | B6: ALC-OFHI | C6: {=iferror(index('4-All Devices'!$A:$BB, match($B6 ,'4-All Devices'!BG:BG,0 ),match(C$4,'4-All Devices'!$4:$4,0)),"")} -> Building Management System | D6: {=iferror(index('4-All Devices'!$A:$BB, match($B6 ,'4-All Devices'!BG:BG,0 ),match(D$4,'4-All Devices'!$4:$4,0)),"")} -> ALC | E6: {=iferror(index('4-All Devices'!$A:$BB, match($B6 ,'4-All Devices'!BG:BG,0 ),match(E$4,'4-All Devices'!$4:$4,0)),"")} -> OFHI | F6: =if(countifs('4-All Devices'!BG:BG,B6)=0,"",countifs('4-All Devices'!BG:BG,B6)) -> 45 | G6: OFHI | H6: 10/100 Mb Half/Full Duplex
A7: =A6+1 -> 3 | B7: SAUTER-EYGT103F001 | C7: {=iferror(index('4-All Devices'!$A:$BB, match($B7 ,'4-All Devices'!BG:BG,0 ),match(C$4,'4-All Devices'!$4:$4,0)),"")} -> Building Management System | D7: {=iferror(index('4-All Devices'!$A:$BB, match($B7 ,'4-All Devices'!BG:BG,0 ),match(D$4,'4-All Devices'!$4:$4,0)),"")} -> SAUTER | E7: {=iferror(index('4-All Devices'!$A:$BB, match($B7 ,'4-All Devices'!BG:BG,0 ),match(E$4,'4-All Devices'!$4:$4,0)),"")} -> EY-GT103F001 | F7: =if(countifs('4-All Devices'!BG:BG,B7)=0,"",countifs('4-All Devices'!BG:BG,B7)) -> 46 | G7: EY-GT103F001 | H7: 10/100 Mb Half/Full Duplex
A8: =A7+1 -> 4 | B8: SAUTER-EYRC504FXXX | C8: {=iferror(index('4-All Devices'!$A:$BB, match($B8 ,'4-All Devices'!BG:BG,0 ),match(C$4,'4-All Devices'!$4:$4,0)),"")} -> Building Management System | D8: {=iferror(index('4-All Devices'!$A:$BB, match($B8 ,'4-All Devices'!BG:BG,0 ),match(D$4,'4-All Devices'!$4:$4,0)),"")} -> SAUTER | E8: {=iferror(index('4-All Devices'!$A:$BB, match($B8 ,'4-All Devices'!BG:BG,0 ),match(E$4,'4-All Devices'!$4:$4,0)),"")} -> EY-RC504FXXX | F8: =if(countifs('4-All Devices'!BG:BG,B8)=0,"",countifs('4-All Devices'!BG:BG,B8)) -> 178 | G8: EY-RC504FXXX | H8: 10/100 Mb Half/Full Duplex
A9: =A8+1 -> 5 | B9: TRANE-TRACERSC | C9: {=iferror(index('4-All Devices'!$A:$BB, match($B9 ,'4-All Devices'!BG:BG,0 ),match(C$4,'4-All Devices'!$4:$4,0)),"")} -> Building Management System | D9: {=iferror(index('4-All Devices'!$A:$BB, match($B9 ,'4-All Devices'!BG:BG,0 ),match(D$4,'4-All Devices'!$4:$4,0)),"")} -> TRANE | E9: {=iferror(index('4-All Devices'!$A:$BB, match($B9 ,'4-All Devices'!BG:BG,0 ),match(E$4,'4-All Devices'!$4:$4,0)),"")} -> TRACER SC+ | F9: =if(countifs('4-All Devices'!BG:BG,B9)=0,"",countifs('4-All Devices'!BG:BG,B9)) -> 2 | G9: TRACER SC+ | H9: 10/100 Mb Half/Full Duplex
A10: =A9+1 -> 6 | B10: TRIDIUM-JACE8000 | C10: {=iferror(index('4-All Devices'!$A:$BB, match($B10 ,'4-All Devices'!BG:BG,0 ),match(C$4,'4-All Devices'!$4:$4,0)),"")} -> Building Management System | D10: {=iferror(index('4-All Devices'!$A:$BB, match($B10 ,'4-All Devices'!BG:BG,0 ),match(D$4,'4-All Devices'!$4:$4,0)),"")} -> Tridium | E10: {=iferror(index('4-All Devices'!$A:$BB, match($B10 ,'4-All Devices'!BG:BG,0 ),match(E$4,'4-All Devices'!$4:$4,0)),"")} -> JACE 8000 | F10: =if(countifs('4-All Devices'!BG:BG,B10)=0,"",countifs('4-All Devices'!BG:BG,B10)) -> 2 | G10: JACE 8000 | H10: 10/100 Mb Half/Full Duplex
A11: =A10+1 -> 7 | B11: NEPTRONIC-EVCBSERIES | C11: {=iferror(index('4-All Devices'!$A:$BB, match($B11 ,'4-All Devices'!BG:BG,0 ),match(C$4,'4-All Devices'!$4:$4,0)),"")} -> Building Management System | D11: {=iferror(index('4-All Devices'!$A:$BB, match($B11 ,'4-All Devices'!BG:BG,0 ),match(D$4,'4-All Devices'!$4:$4,0)),"")} -> Neptronic | E11: {=iferror(index('4-All Devices'!$A:$BB, match($B11 ,'4-All Devices'!BG:BG,0 ),match(E$4,'4-All Devices'!$4:$4,0)),"")} -> EVCB SERIES | F11: =if(countifs('4-All Devices'!BG:BG,B11)=0,"",countifs('4-All Devices'!BG:BG,B11)) -> 2122 | H11: N/A
A12: =A11+1 -> 8 | B12: AQUAGEN-EVCBSERIES | C12: {=iferror(index('4-All Devices'!$A:$BB, match($B12 ,'4-All Devices'!BG:BG,0 ),match(C$4,'4-All Devices'!$4:$4,0)),"")} -> Building Management System | D12: {=iferror(index('4-All Devices'!$A:$BB, match($B12 ,'4-All Devices'!BG:BG,0 ),match(D$4,'4-All Devices'!$4:$4,0)),"")} -> Aquagen | E12: {=iferror(index('4-All Devices'!$A:$BB, match($B12 ,'4-All Devices'!BG:BG,0 ),match(E$4,'4-All Devices'!$4:$4,0)),"")} -> EVCB SERIES | F12: =if(countifs('4-All Devices'!BG:BG,B12)=0,"",countifs('4-All Devices'!BG:BG,B12)) -> 165 | H12: N/A
A13: =A12+1 -> 9 | B13: AQUAGEN-UWM220DN50DN500 | C13: {=iferror(index('4-All Devices'!$A:$BB, match($B13 ,'4-All Devices'!BG:BG,0 ),match(C$4,'4-All Devices'!$4:$4,0)),"")} -> Building Management System | D13: {=iferror(index('4-All Devices'!$A:$BB, match($B13 ,'4-All Devices'!BG:BG,0 ),match(D$4,'4-All Devices'!$4:$4,0)),"")} -> Aquagen | E13: {=iferror(index('4-All Devices'!$A:$BB, match($B13 ,'4-All Devices'!BG:BG,0 ),match(E$4,'4-All Devices'!$4:$4,0)),"")} -> UWM-220 DN-50-DN500 | F13: =if(countifs('4-All Devices'!BG:BG,B13)=0,"",countifs('4-All Devices'!BG:BG,B13)) -> 50 | H13: N/A
A14: =A13+1 -> 10 | B14: DAIKIN-FXZQ32BVM6 | C14: {=iferror(index('4-All Devices'!$A:$BB, match($B14 ,'4-All Devices'!BG:BG,0 ),match(C$4,'4-All Devices'!$4:$4,0)),"")} -> Building Management System | D14: {=iferror(index('4-All Devices'!$A:$BB, match($B14 ,'4-All Devices'!BG:BG,0 ),match(D$4,'4-All Devices'!$4:$4,0)),"")} -> DAIKIN | E14: {=iferror(index('4-All Devices'!$A:$BB, match($B14 ,'4-All Devices'!BG:BG,0 ),match(E$4,'4-All Devices'!$4:$4,0)),"")} -> FXZQ32BVM6 | F14: =if(countifs('4-All Devices'!BG:BG,B14)=0,"",countifs('4-All Devices'!BG:BG,B14)) -> 66 | H14: N/A
A15: =A14+1 -> 11 | B15: EATON-93PR | C15: {=iferror(index('4-All Devices'!$A:$BB, match($B15 ,'4-All Devices'!BG:BG,0 ),match(C$4,'4-All Devices'!$4:$4,0)),"")} -> Building Management System | D15: {=iferror(index('4-All Devices'!$A:$BB, match($B15 ,'4-All Devices'!BG:BG,0 ),match(D$4,'4-All Devices'!$4:$4,0)),"")} -> EATON | E15: {=iferror(index('4-All Devices'!$A:$BB, match($B15 ,'4-All Devices'!BG:BG,0 ),match(E$4,'4-All Devices'!$4:$4,0)),"")} -> 93PR | F15: =if(countifs('4-All Devices'!BG:BG,B15)=0,"",countifs('4-All Devices'!BG:BG,B15)) -> 20 | H15: N/A
A16: =A15+1 -> 12 | B16: EATON-R3G630RB3203 | C16: {=iferror(index('4-All Devices'!$A:$BB, match($B16 ,'4-All Devices'!BG:BG,0 ),match(C$4,'4-All Devices'!$4:$4,0)),"")} -> Building Management System | D16: {=iferror(index('4-All Devices'!$A:$BB, match($B16 ,'4-All Devices'!BG:BG,0 ),match(D$4,'4-All Devices'!$4:$4,0)),"")} -> EATON | E16: {=iferror(index('4-All Devices'!$A:$BB, match($B16 ,'4-All Devices'!BG:BG,0 ),match(E$4,'4-All Devices'!$4:$4,0)),"")} -> R3G630-RB32-03 | F16: =if(countifs('4-All Devices'!BG:BG,B16)=0,"",countifs('4-All Devices'!BG:BG,B16)) -> 1 | H16: N/A
A17: =A16+1 -> 13 | B17: SCHNEIDER-PM2200 | C17: {=iferror(index('4-All Devices'!$A:$BB, match($B17 ,'4-All Devices'!BG:BG,0 ),match(C$4,'4-All Devices'!$4:$4,0)),"")} -> Building Management System | D17: {=iferror(index('4-All Devices'!$A:$BB, match($B17 ,'4-All Devices'!BG:BG,0 ),match(D$4,'4-All Devices'!$4:$4,0)),"")} -> SCHNEIDER | E17: {=iferror(index('4-All Devices'!$A:$BB, match($B17 ,'4-All Devices'!BG:BG,0 ),match(E$4,'4-All Devices'!$4:$4,0)),"")} -> PM2200 | F17: =if(countifs('4-All Devices'!BG:BG,B17)=0,"",countifs('4-All Devices'!BG:BG,B17)) -> 148 | H17: N/A
A18: =A17+1 -> 14 | B18: NICOTRA-DDMP | C18: {=iferror(index('4-All Devices'!$A:$BB, match($B18 ,'4-All Devices'!BG:BG,0 ),match(C$4,'4-All Devices'!$4:$4,0)),"")} -> Building Management System | D18: {=iferror(index('4-All Devices'!$A:$BB, match($B18 ,'4-All Devices'!BG:BG,0 ),match(D$4,'4-All Devices'!$4:$4,0)),"")} -> Nicotra | E18: {=iferror(index('4-All Devices'!$A:$BB, match($B18 ,'4-All Devices'!BG:BG,0 ),match(E$4,'4-All Devices'!$4:$4,0)),"")} -> DDMP | F18: =if(countifs('4-All Devices'!BG:BG,B18)=0,"",countifs('4-All Devices'!BG:BG,B18)) -> 49 | H18: N/A
A19: =A18+1 -> 15 | B19: PVRCONTROLS-CRC202000 | C19: {=iferror(index('4-All Devices'!$A:$BB, match($B19 ,'4-All Devices'!BG:BG,0 ),match(C$4,'4-All Devices'!$4:$4,0)),"")} -> Building Management System | D19: {=iferror(index('4-All Devices'!$A:$BB, match($B19 ,'4-All Devices'!BG:BG,0 ),match(D$4,'4-All Devices'!$4:$4,0)),"")} -> PVR Controls | E19: {=iferror(index('4-All Devices'!$A:$BB, match($B19 ,'4-All Devices'!BG:BG,0 ),match(E$4,'4-All Devices'!$4:$4,0)),"")} -> CRC-202000 | F19: =if(countifs('4-All Devices'!BG:BG,B19)=0,"",countifs('4-All Devices'!BG:BG,B19)) -> 28 | H19: N/A
A20: =A19+1 -> 16 | B20: SCHNEIDER-EASYLOGICEM6436HRS | C20: {=iferror(index('4-All Devices'!$A:$BB, match($B20 ,'4-All Devices'!BG:BG,0 ),match(C$4,'4-All Devices'!$4:$4,0)),"")} -> Building Management System | D20: {=iferror(index('4-All Devices'!$A:$BB, match($B20 ,'4-All Devices'!BG:BG,0 ),match(D$4,'4-All Devices'!$4:$4,0)),"")} -> SCHNEIDER | E20: {=iferror(index('4-All Devices'!$A:$BB, match($B20 ,'4-All Devices'!BG:BG,0 ),match(E$4,'4-All Devices'!$4:$4,0)),"")} -> EASYLOGIC EM6436H RS | F20: =if(countifs('4-All Devices'!BG:BG,B20)=0,"",countifs('4-All Devices'!BG:BG,B20)) -> 100 | H20: N/A
A21: =A20+1 -> 17 | B21: SCHNEIDER-IEM3000 | C21: {=iferror(index('4-All Devices'!$A:$BB, match($B21 ,'4-All Devices'!BG:BG,0 ),match(C$4,'4-All Devices'!$4:$4,0)),"")} -> Building Management System | D21: {=iferror(index('4-All Devices'!$A:$BB, match($B21 ,'4-All Devices'!BG:BG,0 ),match(D$4,'4-All Devices'!$4:$4,0)),"")} -> SCHNEIDER | E21: {=iferror(index('4-All Devices'!$A:$BB, match($B21 ,'4-All Devices'!BG:BG,0 ),match(E$4,'4-All Devices'!$4:$4,0)),"")} -> IEM3000 | F21: =if(countifs('4-All Devices'!BG:BG,B21)=0,"",countifs('4-All Devices'!BG:BG,B21)) -> 68 | H21: N/A
A22: =A21+1 -> 18 | B22: SELECCONTROLS-FLEXYSRAIL | C22: {=iferror(index('4-All Devices'!$A:$BB, match($B22 ,'4-All Devices'!BG:BG,0 ),match(C$4,'4-All Devices'!$4:$4,0)),"")} -> Building Management System | D22: {=iferror(index('4-All Devices'!$A:$BB, match($B22 ,'4-All Devices'!BG:BG,0 ),match(D$4,'4-All Devices'!$4:$4,0)),"")} -> SELEC CONTROLS | E22: {=iferror(index('4-All Devices'!$A:$BB, match($B22 ,'4-All Devices'!BG:BG,0 ),match(E$4,'4-All Devices'!$4:$4,0)),"")} -> FLEXYS RAIL | F22: =if(countifs('4-All Devices'!BG:BG,B22)=0,"",countifs('4-All Devices'!BG:BG,B22)) -> 2 | H22: N/A
A23: =A22+1 -> 19 | B23: DAIKIN-DTA116A51 | C23: {=iferror(index('4-All Devices'!$A:$BB, match($B23 ,'4-All Devices'!BG:BG,0 ),match(C$4,'4-All Devices'!$4:$4,0)),"")} -> Building Management System | D23: {=iferror(index('4-All Devices'!$A:$BB, match($B23 ,'4-All Devices'!BG:BG,0 ),match(D$4,'4-All Devices'!$4:$4,0)),"")} -> DAIKIN | E23: {=iferror(index('4-All Devices'!$A:$BB, match($B23 ,'4-All Devices'!BG:BG,0 ),match(E$4,'4-All Devices'!$4:$4,0)),"")} -> DTA116A51 | F23: =if(countifs('4-All Devices'!BG:BG,B23)=0,"",countifs('4-All Devices'!BG:BG,B23)) -> 1 | H23: N/A
A24: =A23+1 -> 20 | C24: {=iferror(index('4-All Devices'!$A:$BB, match($B24 ,'4-All Devices'!BG:BG,0 ),match(C$4,'4-All Devices'!$4:$4,0)),"")} | D24: {=iferror(index('4-All Devices'!$A:$BB, match($B24 ,'4-All Devices'!BG:BG,0 ),match(D$4,'4-All Devices'!$4:$4,0)),"")} | E24: {=iferror(index('4-All Devices'!$A:$BB, match($B24 ,'4-All Devices'!BG:BG,0 ),match(E$4,'4-All Devices'!$4:$4,0)),"")} | F24: =if(countifs('4-All Devices'!BG:BG,B24)=0,"",countifs('4-All Devices'!BG:BG,B24))
A25: =A24+1 -> 21 | C25: {=iferror(index('4-All Devices'!$A:$BB, match($B25 ,'4-All Devices'!BG:BG,0 ),match(C$4,'4-All Devices'!$4:$4,0)),"")} | D25: {=iferror(index('4-All Devices'!$A:$BB, match($B25 ,'4-All Devices'!BG:BG,0 ),match(D$4,'4-All Devices'!$4:$4,0)),"")} | E25: {=iferror(index('4-All Devices'!$A:$BB, match($B25 ,'4-All Devices'!BG:BG,0 ),match(E$4,'4-All Devices'!$4:$4,0)),"")} | F25: =if(countifs('4-All Devices'!BG:BG,B25)=0,"",countifs('4-All Devices'!BG:BG,B25))
A26: =A25+1 -> 22 | C26: {=iferror(index('4-All Devices'!$A:$BB, match($B26 ,'4-All Devices'!BG:BG,0 ),match(C$4,'4-All Devices'!$4:$4,0)),"")} | D26: {=iferror(index('4-All Devices'!$A:$BB, match($B26 ,'4-All Devices'!BG:BG,0 ),match(D$4,'4-All Devices'!$4:$4,0)),"")} | E26: {=iferror(index('4-All Devices'!$A:$BB, match($B26 ,'4-All Devices'!BG:BG,0 ),match(E$4,'4-All Devices'!$4:$4,0)),"")} | F26: =if(countifs('4-All Devices'!BG:BG,B26)=0,"",countifs('4-All Devices'!BG:BG,B26))
A27: =A26+1 -> 23 | C27: {=iferror(index('4-All Devices'!$A:$BB, match($B27 ,'4-All Devices'!BG:BG,0 ),match(C$4,'4-All Devices'!$4:$4,0)),"")} | D27: {=iferror(index('4-All Devices'!$A:$BB, match($B27 ,'4-All Devices'!BG:BG,0 ),match(D$4,'4-All Devices'!$4:$4,0)),"")} | E27: {=iferror(index('4-All Devices'!$A:$BB, match($B27 ,'4-All Devices'!BG:BG,0 ),match(E$4,'4-All Devices'!$4:$4,0)),"")} | F27: =if(countifs('4-All Devices'!BG:BG,B27)=0,"",countifs('4-All Devices'!BG:BG,B27))
A28: =A27+1 -> 24 | C28: {=iferror(index('4-All Devices'!$A:$BB, match($B28 ,'4-All Devices'!BG:BG,0 ),match(C$4,'4-All Devices'!$4:$4,0)),"")} | D28: {=iferror(index('4-All Devices'!$A:$BB, match($B28 ,'4-All Devices'!BG:BG,0 ),match(D$4,'4-All Devices'!$4:$4,0)),"")} | E28: {=iferror(index('4-All Devices'!$A:$BB, match($B28 ,'4-All Devices'!BG:BG,0 ),match(E$4,'4-All Devices'!$4:$4,0)),"")} | F28: =if(countifs('4-All Devices'!BG:BG,B28)=0,"",countifs('4-All Devices'!BG:BG,B28))
A29: =A28+1 -> 25 | C29: {=iferror(index('4-All Devices'!$A:$BB, match($B29 ,'4-All Devices'!BG:BG,0 ),match(C$4,'4-All Devices'!$4:$4,0)),"")} | D29: {=iferror(index('4-All Devices'!$A:$BB, match($B29 ,'4-All Devices'!BG:BG,0 ),match(D$4,'4-All Devices'!$4:$4,0)),"")} | E29: {=iferror(index('4-All Devices'!$A:$BB, match($B29 ,'4-All Devices'!BG:BG,0 ),match(E$4,'4-All Devices'!$4:$4,0)),"")} | F29: =if(countifs('4-All Devices'!BG:BG,B29)=0,"",countifs('4-All Devices'!BG:BG,B29))
A30: =A29+1 -> 26 | C30: {=iferror(index('4-All Devices'!$A:$BB, match($B30 ,'4-All Devices'!BG:BG,0 ),match(C$4,'4-All Devices'!$4:$4,0)),"")} | D30: {=iferror(index('4-All Devices'!$A:$BB, match($B30 ,'4-All Devices'!BG:BG,0 ),match(D$4,'4-All Devices'!$4:$4,0)),"")} | E30: {=iferror(index('4-All Devices'!$A:$BB, match($B30 ,'4-All Devices'!BG:BG,0 ),match(E$4,'4-All Devices'!$4:$4,0)),"")} | F30: =if(countifs('4-All Devices'!BG:BG,B30)=0,"",countifs('4-All Devices'!BG:BG,B30))
A31: =A30+1 -> 27 | C31: {=iferror(index('4-All Devices'!$A:$BB, match($B31 ,'4-All Devices'!BG:BG,0 ),match(C$4,'4-All Devices'!$4:$4,0)),"")} | D31: {=iferror(index('4-All Devices'!$A:$BB, match($B31 ,'4-All Devices'!BG:BG,0 ),match(D$4,'4-All Devices'!$4:$4,0)),"")} | E31: {=iferror(index('4-All Devices'!$A:$BB, match($B31 ,'4-All Devices'!BG:BG,0 ),match(E$4,'4-All Devices'!$4:$4,0)),"")} | F31: =if(countifs('4-All Devices'!BG:BG,B31)=0,"",countifs('4-All Devices'!BG:BG,B31))
A32: =A31+1 -> 28 | C32: {=iferror(index('4-All Devices'!$A:$BB, match($B32 ,'4-All Devices'!BG:BG,0 ),match(C$4,'4-All Devices'!$4:$4,0)),"")} | D32: {=iferror(index('4-All Devices'!$A:$BB, match($B32 ,'4-All Devices'!BG:BG,0 ),match(D$4,'4-All Devices'!$4:$4,0)),"")} | E32: {=iferror(index('4-All Devices'!$A:$BB, match($B32 ,'4-All Devices'!BG:BG,0 ),match(E$4,'4-All Devices'!$4:$4,0)),"")} | F32: =if(countifs('4-All Devices'!BG:BG,B32)=0,"",countifs('4-All Devices'!BG:BG,B32))
A33: =A32+1 -> 29 | C33: {=iferror(index('4-All Devices'!$A:$BB, match($B33 ,'4-All Devices'!BG:BG,0 ),match(C$4,'4-All Devices'!$4:$4,0)),"")} | D33: {=iferror(index('4-All Devices'!$A:$BB, match($B33 ,'4-All Devices'!BG:BG,0 ),match(D$4,'4-All Devices'!$4:$4,0)),"")} | E33: {=iferror(index('4-All Devices'!$A:$BB, match($B33 ,'4-All Devices'!BG:BG,0 ),match(E$4,'4-All Devices'!$4:$4,0)),"")} | F33: =if(countifs('4-All Devices'!BG:BG,B33)=0,"",countifs('4-All Devices'!BG:BG,B33))
A34: =A33+1 -> 30 | C34: {=iferror(index('4-All Devices'!$A:$BB, match($B34 ,'4-All Devices'!BG:BG,0 ),match(C$4,'4-All Devices'!$4:$4,0)),"")} | D34: {=iferror(index('4-All Devices'!$A:$BB, match($B34 ,'4-All Devices'!BG:BG,0 ),match(D$4,'4-All Devices'!$4:$4,0)),"")} | E34: {=iferror(index('4-All Devices'!$A:$BB, match($B34 ,'4-All Devices'!BG:BG,0 ),match(E$4,'4-All Devices'!$4:$4,0)),"")} | F34: =if(countifs('4-All Devices'!BG:BG,B34)=0,"",countifs('4-All Devices'!BG:BG,B34))
A35: =A34+1 -> 31 | C35: {=iferror(index('4-All Devices'!$A:$BB, match($B35 ,'4-All Devices'!BG:BG,0 ),match(C$4,'4-All Devices'!$4:$4,0)),"")} | D35: {=iferror(index('4-All Devices'!$A:$BB, match($B35 ,'4-All Devices'!BG:BG,0 ),match(D$4,'4-All Devices'!$4:$4,0)),"")} | E35: {=iferror(index('4-All Devices'!$A:$BB, match($B35 ,'4-All Devices'!BG:BG,0 ),match(E$4,'4-All Devices'!$4:$4,0)),"")} | F35: =if(countifs('4-All Devices'!BG:BG,B35)=0,"",countifs('4-All Devices'!BG:BG,B35))
... A104: =A103+1 -> 100 | C104: {=iferror(index('4-All Devices'!$A:$BB, match($B104 ,'4-All Devices'!BG:BG,0 ),match(C$4,'4-All Devices'!$4:$4,0)),"")} | D104: {=iferror(index('4-All Devices'!$A:$BB, match($B104 ,'4-All Devices'!BG:BG,0 ),match(D$4,'4-All Devices'!$4:$4,0)),"")} | E104: {=iferror(index('4-All Devices'!$A:$BB, match($B104 ,'4-All Devices'!BG:BG,0 ),match(E$4,'4-All Devices'!$4:$4,0)),"")} | F104: =if(countifs('4-All Devices'!BG:BG,B104)=0,"",countifs('4-All Devices'!BG:BG,B104))

Sheet 4-All Devices
B1: General Device Info | O1: QR Code Info | S1: Install Info | V1: Firmware Version | Y1: Protocol Info | Z1: BACnet Information | AB1: ModBus Information | AC1: LONWorks Information | AD1: Any Other Protocol | AE1: Network Information | AH1: IP Network Information | AN1: GEN Network Switch Information | AR1: IP Peer - Peer Comms | AV1: MQTT | AW1: Serial Comms | AX1: Connection Type | AY1: Condition Assessment | BB1: Qualification | BC1: Photos | BD1: Owner | BE1: Comments | BF1: Not to be filled
A2: To be filled by: | B2: System Owner | O2: MSI (Smart Ready) / System Owner (Cyber Compliant) | S2: System Owner | V2: System Owner | Y2: System Owner | AE2: MSI (Smart Ready) / System Owner (Cyber Compliant) | AF2: System Owner | AG2: SME - Info via CorpEng BASE after Device Enrolment (GUTS Ticket) | AH2: System Owner | AK2: SME - Info via EFIM after Device Enrollment (GUTS Ticket) [C39 Overview] | AM2: System Owner | AN2: SME - Imported from GTE Dashboard | AQ2: System Owner | AR2: System Owner | AY2: FM | BB2: System Owner | BC2: DBRS Surveyor | BD2: System Owner | BE2: Comments
A3: Notes | B3: Specify the system the device is used for. (E.g. From Dropdown) | C3: Specify the asset name as defined in the BOS Naming and Labeling Standard (E.g. DDC-1, HLI-2 etc.) | D3: If asset name cannot be assigned in the device due to technical or regional reasons, or if this is an audit, specify the user defined asset name as recorded on the device or software (E.g. as entered on the device or in the software etc.) | E3: Specify the manufacturer of the device. (E.g. Tridium, EasyIO, Schneider) | F3: Specify the model type / number of the device. (E.g. JACE8000, FS-32, ASP) | G3: Specify the Asset Rank (e.g. Low, Standard, Critical, Life Safety) | H3: Specify the communication type (e.g. IP or serial i.e. RS485) | I3: Specify the function the device is used for. (e.g. FCU, AHU, LTGW, etc.) for example if a DDC controller was on a FCU, enter FCU. See this link | J3: Specify the floor on which the device is installed. (E.g. 1, 2, 3) | K3: Specify the location of the Device based on the REWS ID in FloorScope. (E.g. 101, B155, etc.) or if on New Construction, the Construction ID | L3: Specify the control panel reference for the device if applicable. (E.g. CTRP-1) | M3: Enter the serial number from the device (E.g. S/N 1524342) | N3: Perform a check to confirm status (Including end to end checks to headend. (E.g.Active, Retired) | O3: Specify if QR Code has been applied to the Device (E.g. Yes) | P3: Human readable QR code that gets printed on the QR code label prefix_AssetName_suffix where prefix is optional site name and suffix is optional FM description (E.g. DDC-1_1-Boilers, LTHW-3_1-3) | Q3: Specify the GUID. examples - If BIM: ifc://04aEp5ymD_$u5IxhJN2aGi If not BIM: uuid://d3501378-dd50-47c5-ae26-806726e1b749 Can be generated using the menu Add-Ons > Insert > Insert GUID | R3: Auto Generated | S3: Please enter the installation Vendors name if known (E.g. ACME controls) | T3: Enter the Start Date for Warranty (PC date for New Construction) Or Install Date if no Warranty (Use US Format mm/dd/yy) | U3: Enter the end Date for Warranty (Use US Format mm/dd/yy) | V3: Specify the software version of the device (e.g. xxxxxx) | W3: Specify the Default Firmware Version of the device when installed on the project. (E.g. 2.3.0.1) | X3: Specify the Upgraded Firmware Version of the device if upgraded during the project. (Note: Any new firmware requires qualification) (E.g. 2.3.2.5) | Y3: Specify the control protocol(s) used by the device. (E.g. BACnet IP & MQTT) If there are multiple protocols used by the Device, add them to the comments column | Z3: Specify the BACnet Address of the device if the device supports BACnet Protocol. (E.g. 123456) | AA3: Specify the Network Number configured for the device if the device supports BACnet Protocol. (E.g. 1) (Note: This should be as per manufacturer's guidance)) | AB3: Specify the Modbus ID of the device if the device supports Modbus Protocol. (E.g. 10,11,12) | AC3: Specify the Neuron ID of the device if the device supports LONWorks Protocol. (E.g. 04ab345dfk97) | AD3: Specify the Device ID for devices such as DALI, MBUS, BACNet MSTP "MAC" Address or any other ID that would be useful to record. Max 30 Characters. | AE3: Enter Corphosting State Corphosted: Corphosting complete None:- No Corphosting Required Add: create a Corphosting request Modify: Corphosting needs changing Delete: Remove Corphosting | AF3: Specify the Ethernet MAC Address of the device. (E.g. 1A:2B:3C:4D:5E:6F) **Required for hosting the device on Google GEN network** | AG3: HostName Auto Generated from Building Name and QR Code Asset Name | AH3: Specify the Private IP Address used for commissioning the device on a private network. (E.g. 192.168.10.1) | AI3: Specify the Private Subnet Mask used for commissioning the device on a private network. (E.g. 255.255.255.0) | AJ3: Specify the default gateway used for commissioning the device on a private network. (E.g. 192.168.0.1) | AK3: This information will be supplied by EFIM-Ops when the devices are provisioned. DHCP assigned Corp IP Address should be entered here. Devices should not be assigned a static IP address (E.g. 172.28.68.1) | AL3: This information will be supplied by EFIM-Ops when the devices are provisioned and it should be documented here. Specify the Corp Subnet Mask assigned the device by the DHCP Server on the Corp Network. (E.g. 255.254.0.0) | AM3: Specify whether PoE is required and which standard (E.g. None, PoE, PoE+) Supported Types: IEEE 802.3af (a.k.a PoE Type 1) up to 15.4 watts IEEE 802.3at (a.k.a PoE+ or PoE Type 2) up to 30 watts Note: UPOE+ for specific use cases ONLY, pending review and approval. | AN3: Specify the Location or panel number (marked up on floorscope of GDesign) for the switch this particular device is connected to. (E.g. IDF-01-01) | AO3: Specify the Switch Name to which the device is connected. (E.g. LABSW1-2-3) Note: Un-managed may not be labelled, note the make instead. | AP3: Specify the Switch Port ID to which the device is connected. (E.g.12) | AQ3: Specify the Jack Label Number to which the device is connected. (E.g. BMS1.2-034) | AR3: Specify if the device is a Primary Device or Secondary Device TO ANY OTHER DEVICE. Secondary is controlled by a Primary (E.g. Primary TO XYZ, Secondary TO XYZ ) | AS3: Specify the Protocol(s) & Ports used by the device for peer-to-peer comms. (E.g. Port:Service:Protocol) | AT3: Specify the Endpoint/s the device communicates to for peer-to-peer comms. (E.g. Controller Name or Headend PC) | AU3: Specify the IP Packet Transmission method used by the device communicates for peer-to-peer comms. (E.g. Unicast, MultiCast, Broadcast) | AV3: Specify whether MQTT has been implemented on the device? (E.g. Yes/No) | AW3: If the device is a secondary device on a serial network, specify the primary controller it reports to (E.g. HLI-1) | AX3: Specify the device connection type to cloud? (E.g. Gateway device/Direct Device/Proxied Device) | AY3: FM to confirm Condition of equipment. (E.g.Excellent, Good, Fair, Poor, Offline) | AZ3: FM to enter the maintenance provider for the equipment (E.g.Acme Controls, Sauter, AAA Lighting Solutions) | BA3: FM to enter the expected life expectancy. (in years E.g.5, 10, 20. Integers only) | BB3: Specify if the device has been put through device qualification process . (E.g. Yes/No) | BC3: Provide a link to the drive folder for the site where any relevant photos are stored (E.g. http://drive.google.com/ghoaiab7rgai4 PASTE FILE LINK URL DIRECTLY TO CELL, DO NOT LINK CELL TO URL) | BD3: Select which Google partner is the device owner. (E.g. WS/Facilities, Food, GFit, Events, GEN, BOPS/AV, SecOps, Landlord, Unknown, Other) | BE3: Provide any comments if applicable. | BF3: This column represents the "device type" for IP devices. Only used for corphosting <manufacturer>_<model> | BG3: This column represents a Device Lookup ID to link to the device types tab
A4: No. | B4: System | C4: Device/Asset role name (asset.name) | D4: User Defined Device Name | E4: Device / Asset Manufacturer | F4: Device / Asset Model (manufacturer) | G4: Device / Asset Rank | H4: Communication Type | I4: Asset Function | J4: Floor | K4: Location | L4: Panel Reference | M4: Manufacturer Provided Device / Asset Serial Number | N4: Device / Asset Status | O4: QR Code Applied? | P4: Human readable QR code | Q4: GUID | R4: QR Code Payload | S4: Installers Name | T4: Warranty Start Date/ Install Date | U4: Warranty End Date | V4: Device / Asset Software (OS) Version | W4: Default Firmware Version | X4: Current Firmware Version | Y4: Protocol | Z4: BACNet Device Number | AA4: Bacnet Network Number | AB4: Modbus Address | AC4: Neuron ID | AD4: Device ID & Any Other Information | AE4: CorpHosting | AF4: Ethernet MAC Address | AG4: Assigned Hostname | AH4: Private IP Address | AI4: Private Subnet Mask | AJ4: Private Gateway | AK4: Corp IP Address | AL4: Corp IP Subnet Mask (Netblock) | AM4: Power over Ethernet | AN4: Switch Location | AO4: Switch Name | AP4: Switch Port ID | AQ4: Jack Label | AR4: Primary/Secondary | AS4: Protocol/s & Ports | AT4: Endpoint/s | AU4: IP Packet Transmission | AV4: MQTT Implemented | AW4: Serial Relationships | AX4: Device Connection Type | AY4: Condition Assessment | AZ4: Maintenance Provider | BA4: Expected Lifespan | BB4: Device / Asset Qualified | BC4: Photos/Snapshots - Link to Device Photo | BD4: Device Owner | BE4: Comments | BF4: Corphosting Device Types | BG4: Device Lookup ID with Firmware
A5: 1 | B5: Building Management System | C5: DDC-201 | D5: DDC-201 | E5: SAUTER | F5: EY-RC504FXXX | G5: Standard | H5: IP (Wired GEN BOS-IoT) | I5: DDC | J5: B3 | K5: B3V08 | L5: HVACCP-201 | M5: 411001239390 | N5: Active | O5: Yes | P5: =CONCATENATE("IN-BLR-ANANTA-",C5,"_",J5) -> IN-BLR-ANANTA-DDC-201_B3 | Q5: uuid://623aa24f-fcb2-449d-b411-c0aae1f7599f | R5: =IFS(C5="","",C5="n/a","N/A",LEN(C5),Concatenate("{",char(34),"asset",char(34),":{",char(34),"guid",char(34),":",char(34),Q5,char(34),",",char(34),"site",char(34),":",char(34),LOWER('2-Building'!$B$4),char(34),",",char(34),"name",char(34),":",char(34),LOWER(C5),char(34),"}}")) -> {"asset":{"guid":"uuid://623aa24f-fcb2-449d-b411-c0aae1f7599f","site":"in-blr-ananta","name":"ddc-201"}} | S5: Eneffen | V5: 2.23 | W5: V3.4 | X5: 5.0.1 | Y5: BACnet IP | Z5: 14001 | AA5: 11501 | AE5: Corphosted | AF5: 5C:C2:13:05:DA:58 | AG5: =IFS(LEN(AF5)=17,LOWER('2-Building'!$B$4 & "-" & C5), AF5="N/A", "N/A", LEN(AF5)=0,"") -> in-blr-ananta-ddc-201 | AK5: 100.95.214.178 | AL5: 255.255.240.0 | AM5: None | AR5: Primary | AS5: BACnet,47808 | AT5: DDC-1 | AU5: Unicast | AV5: No | AW5: N/A | AX5: Gateway Device | AY5: Good | AZ5: Eneffen | BA5: 10 | BB5: Yes | BD5: Landlord | BE5: Basebuilder System and connected on Gen Network | BF5: =IFERROR(__xludf.DUMMYFUNCTION("LOWER(Regexreplace(to_text(E5),""[^A-Za-z0-9]"","""")&""_""&Regexreplace(to_text(F5),""[^A-Za-z0-9]"",""""))"),"sauter_eyrc504fxxx") -> sauter_eyrc504fxxx | BG5: =IFERROR(__xludf.DUMMYFUNCTION("upper(Regexreplace(to_text(E5),""[^A-Za-z0-9]"","""")&""-""&Regexreplace(to_text(F5),""[^A-Za-z0-9]"",""""))"),"SAUTER-EYRC504FXXX") -> SAUTER-EYRC504FXXX
A6: 2 | B6: Building Management System | C6: DDC-202 | D6: DDC-202 | E6: SAUTER | F6: EY-RC504FXXX | G6: Standard | H6: IP (Wired GEN BOS-IoT) | I6: DDC | J6: B3 | K6: B3V08 | L6: HVACCP-201 | M6: 411001235150 | N6: Active | O6: Yes | P6: =CONCATENATE("IN-BLR-ANANTA-",C6,"_",J6) -> IN-BLR-ANANTA-DDC-202_B3 | Q6: uuid://798bc407-23a3-4137-8f8a-46574963c835 | R6: =IFS(C6="","",C6="n/a","N/A",LEN(C6),Concatenate("{",char(34),"asset",char(34),":{",char(34),"guid",char(34),":",char(34),Q6,char(34),",",char(34),"site",char(34),":",char(34),LOWER('2-Building'!$B$4),char(34),",",char(34),"name",char(34),":",char(34),LOWER(C6),char(34),"}}")) -> {"asset":{"guid":"uuid://798bc407-23a3-4137-8f8a-46574963c835","site":"in-blr-ananta","name":"ddc-202"}} | S6: Eneffen | V6: 2.23 | W6: V3.4 | X6: 5.0.1 | Y6: BACnet IP | Z6: 14002 | AA6: 11501 | AE6: Corphosted | AF6: 5C:C2:13:05:DD:6C | AG6: =IFS(LEN(AF6)=17,LOWER('2-Building'!$B$4 & "-" & C6), AF6="N/A", "N/A", LEN(AF6)=0,"") -> in-blr-ananta-ddc-202 | AK6: 100.95.214.200 | AL6: 255.255.240.0 | AM6: None | AR6: Primary | AS6: BACnet,47808 | AT6: HLI-101 | AU6: Unicast | AV6: No | AW6: N/A | AX6: Gateway Device | AY6: Good | AZ6: Eneffen | BA6: 10 | BB6: Yes | BD6: Landlord | BE6: Basebuilder System and connected on Gen Network | BF6: =IFERROR(__xludf.DUMMYFUNCTION("LOWER(Regexreplace(to_text(E6),""[^A-Za-z0-9]"","""")&""_""&Regexreplace(to_text(F6),""[^A-Za-z0-9]"",""""))"),"sauter_eyrc504fxxx") -> sauter_eyrc504fxxx | BG6: =IFERROR(__xludf.DUMMYFUNCTION("upper(Regexreplace(to_text(E6),""[^A-Za-z0-9]"","""")&""-""&Regexreplace(to_text(F6),""[^A-Za-z0-9]"",""""))"),"SAUTER-EYRC504FXXX") -> SAUTER-EYRC504FXXX
A7: 3 | B7: Building Management System | C7: DDC-203 | D7: DDC-203 | E7: SAUTER | F7: EY-RC504FXXX | G7: Standard | H7: IP (Wired GEN BOS-IoT) | I7: DDC | J7: B3 | K7: B3V08 | L7: HVACCP-202 | M7: 411001359983 | N7: Active | O7: Yes | P7: =CONCATENATE("IN-BLR-ANANTA-",C7,"_",J7) -> IN-BLR-ANANTA-DDC-203_B3 | Q7: uuid://e2145a43-9f4c-452b-b41f-57bcd01c89c9 | R7: =IFS(C7="","",C7="n/a","N/A",LEN(C7),Concatenate("{",char(34),"asset",char(34),":{",char(34),"guid",char(34),":",char(34),Q7,char(34),",",char(34),"site",char(34),":",char(34),LOWER('2-Building'!$B$4),char(34),",",char(34),"name",char(34),":",char(34),LOWER(C7),char(34),"}}")) -> {"asset":{"guid":"uuid://e2145a43-9f4c-452b-b41f-57bcd01c89c9","site":"in-blr-ananta","name":"ddc-203"}} | S7: Eneffen | V7: 2.23 | W7: V3.4 | X7: 5.0.1 | Y7: BACnet IP | Z7: 14003 | AA7: 11501 | AE7: Corphosted | AF7: 5C:C2:13:06:8D:77 | AG7: =IFS(LEN(AF7)=17,LOWER('2-Building'!$B$4 & "-" & C7), AF7="N/A", "N/A", LEN(AF7)=0,"") -> in-blr-ananta-ddc-203 | AK7: 100.95.214.207 | AL7: 255.255.240.0 | AM7: None | AR7: Primary | AS7: BACnet,47808 | AT7: HLI-101 | AU7: Unicast | AV7: No | AW7: N/A | AX7: Gateway Device | AY7: Good | AZ7: Eneffen | BA7: 10 | BB7: Yes | BD7: Landlord | BE7: Basebuilder System and connected on Gen Network | BF7: =IFERROR(__xludf.DUMMYFUNCTION("LOWER(Regexreplace(to_text(E7),""[^A-Za-z0-9]"","""")&""_""&Regexreplace(to_text(F7),""[^A-Za-z0-9]"",""""))"),"sauter_eyrc504fxxx") -> sauter_eyrc504fxxx | BG7: =IFERROR(__xludf.DUMMYFUNCTION("upper(Regexreplace(to_text(E7),""[^A-Za-z0-9]"","""")&""-""&Regexreplace(to_text(F7),""[^A-Za-z0-9]"",""""))"),"SAUTER-EYRC504FXXX") -> SAUTER-EYRC504FXXX
A8: 4 | B8: Building Management System | C8: DDC-204 | D8: DDC-204 | E8: SAUTER | F8: EY-RC504FXXX | G8: Standard | H8: IP (Wired GEN BOS-IoT) | I8: DDC | J8: B2 | K8: B207 | L8: HVACCP-203 | M8: 411001359577 | N8: Active | O8: Yes | P8: =CONCATENATE("IN-BLR-ANANTA-",C8,"_",J8) -> IN-BLR-ANANTA-DDC-204_B2 | Q8: uuid://815b19a3-96f5-4fd5-8b77-7e10541a6811 | R8: =IFS(C8="","",C8="n/a","N/A",LEN(C8),Concatenate("{",char(34),"asset",char(34),":{",char(34),"guid",char(34),":",char(34),Q8,char(34),",",char(34),"site",char(34),":",char(34),LOWER('2-Building'!$B$4),char(34),",",char(34),"name",char(34),":",char(34),LOWER(C8),char(34),"}}")) -> {"asset":{"guid":"uuid://815b19a3-96f5-4fd5-8b77-7e10541a6811","site":"in-blr-ananta","name":"ddc-204"}} | S8: Eneffen | V8: 2.23 | W8: V3.4 | X8: 5.0.1 | Y8: BACnet IP | Z8: 14004 | AA8: 11501 | AE8: Corphosted | AF8: 5C:C2:13:06:87:66 | AG8: =IFS(LEN(AF8)=17,LOWER('2-Building'!$B$4 & "-" & C8), AF8="N/A", "N/A", LEN(AF8)=0,"") -> in-blr-ananta-ddc-204 | AK8: 100.95.214.199 | AL8: 255.255.240.0 | AM8: None | AR8: Primary | AS8: BACnet,47808 | AT8: HLI-101 | AU8: Unicast | AV8: No | AW8: N/A | AX8: Gateway Device | AY8: Good | AZ8: Eneffen | BA8: 10 | BB8: Yes | BD8: Landlord | BE8: Basebuilder System and connected on Gen Network | BF8: =IFERROR(__xludf.DUMMYFUNCTION("LOWER(Regexreplace(to_text(E8),""[^A-Za-z0-9]"","""")&""_""&Regexreplace(to_text(F8),""[^A-Za-z0-9]"",""""))"),"sauter_eyrc504fxxx") -> sauter_eyrc504fxxx | BG8: =IFERROR(__xludf.DUMMYFUNCTION("upper(Regexreplace(to_text(E8),""[^A-Za-z0-9]"","""")&""-""&Regexreplace(to_text(F8),""[^A-Za-z0-9]"",""""))"),"SAUTER-EYRC504FXXX") -> SAUTER-EYRC504FXXX
A9: 5 | B9: Building Management System | C9: DDC-205 | D9: DDC-205 | E9: SAUTER | F9: EY-RC504FXXX | G9: Standard | H9: IP (Wired GEN BOS-IoT) | I9: DDC | J9: B2 | K9: B207 | L9: HVACCP-204 | M9: 411001359983 | N9: Active | O9: Yes | P9: =CONCATENATE("IN-BLR-ANANTA-",C9,"_",J9) -> IN-BLR-ANANTA-DDC-205_B2 | Q9: uuid://88a7e6e1-4067-4025-9497-a7b066e9a6f6 | R9: =IFS(C9="","",C9="n/a","N/A",LEN(C9),Concatenate("{",char(34),"asset",char(34),":{",char(34),"guid",char(34),":",char(34),Q9,char(34),",",char(34),"site",char(34),":",char(34),LOWER('2-Building'!$B$4),char(34),",",char(34),"name",char(34),":",char(34),LOWER(C9),char(34),"}}")) -> {"asset":{"guid":"uuid://88a7e6e1-4067-4025-9497-a7b066e9a6f6","site":"in-blr-ananta","name":"ddc-205"}} | S9: Eneffen | V9: 2.23 | W9: V3.4 | X9: 5.0.1 | Y9: BACnet IP | Z9: 14005 | AA9: 11501 | AE9: Corphosted | AF9: 5C:C2:13:05:DA:45 | AG9: =IFS(LEN(AF9)=17,LOWER('2-Building'!$B$4 & "-" & C9), AF9="N/A", "N/A", LEN(AF9)=0,"") -> in-blr-ananta-ddc-205 | AK9: 100.95.214.179 | AL9: 255.255.240.0 | AM9: None | AR9: Primary | AS9: BACnet,47808 | AT9: DDC-1 | AU9: Unicast | AV9: No | AW9: N/A | AX9: Gateway Device | AY9: Good | AZ9: Eneffen | BA9: 10 | BB9: Yes | BD9: Landlord | BE9: Basebuilder System and connected on Gen Network | BF9: =IFERROR(__xludf.DUMMYFUNCTION("LOWER(Regexreplace(to_text(E9),""[^A-Za-z0-9]"","""")&""_""&Regexreplace(to_text(F9),""[^A-Za-z0-9]"",""""))"),"sauter_eyrc504fxxx") -> sauter_eyrc504fxxx | BG9: =IFERROR(__xludf.DUMMYFUNCTION("upper(Regexreplace(to_text(E9),""[^A-Za-z0-9]"","""")&""-""&Regexreplace(to_text(F9),""[^A-Za-z0-9]"",""""))"),"SAUTER-EYRC504FXXX") -> SAUTER-EYRC504FXXX
A10: 6 | B10: Building Management System | C10: DDC-206 | D10: DDC-206 | E10: SAUTER | F10: EY-RC504FXXX | G10: Standard | H10: IP (Wired GEN BOS-IoT) | I10: DDC | J10: B2 | K10: B209 | L10: HVACCP-205 | M10: 411001360022 | N10: Active | O10: Yes | P10: =CONCATENATE("IN-BLR-ANANTA-",C10,"_",J10) -> IN-BLR-ANANTA-DDC-206_B2 | Q10: uuid://651ca8e1-1d12-4d21-9040-97b089d55d78 | R10: =IFS(C10="","",C10="n/a","N/A",LEN(C10),Concatenate("{",char(34),"asset",char(34),":{",char(34),"guid",char(34),":",char(34),Q10,char(34),",",char(34),"site",char(34),":",char(34),LOWER('2-Building'!$B$4),char(34),",",char(34),"name",char(34),":",char(34),LOWER(C10),char(34),"}}")) -> {"asset":{"guid":"uuid://651ca8e1-1d12-4d21-9040-97b089d55d78","site":"in-blr-ananta","name":"ddc-206"}} | S10: Eneffen | V10: 2.23 | W10: V3.4 | X10: 5.0.1 | Y10: BACnet IP | Z10: 14006 | AA10: 11501 | AE10: Corphosted | AF10: 5C:C2:13:06:85:DD | AG10: =IFS(LEN(AF10)=17,LOWER('2-Building'!$B$4 & "-" & C10), AF10="N/A", "N/A", LEN(AF10)=0,"") -> in-blr-ananta-ddc-206 | AK10: 100.95.214.164 | AL10: 255.255.240.0 | AM10: None | AR10: Primary | AS10: BACnet,47808 | AT10: HLI-101 | AU10: Unicast | AV10: No | AW10: N/A | AX10: Gateway Device | AY10: Good | AZ10: Eneffen | BA10: 10 | BB10: Yes | BD10: Landlord | BE10: Basebuilder System and connected on Gen Network | BF10: =IFERROR(__xludf.DUMMYFUNCTION("LOWER(Regexreplace(to_text(E10),""[^A-Za-z0-9]"","""")&""_""&Regexreplace(to_text(F10),""[^A-Za-z0-9]"",""""))"),"sauter_eyrc504fxxx") -> sauter_eyrc504fxxx | BG10: =IFERROR(__xludf.DUMMYFUNCTION("upper(Regexreplace(to_text(E10),""[^A-Za-z0-9]"","""")&""-""&Regexreplace(to_text(F10),""[^A-Za-z0-9]"",""""))"),"SAUTER-EYRC504FXXX") -> SAUTER-EYRC504FXXX
A11: 7 | B11: Building Management System | C11: DDC-207 | D11: DDC-207 | E11: SAUTER | F11: EY-RC504FXXX | G11: Standard | H11: IP (Wired GEN BOS-IoT) | I11: DDC | J11: B1 | K11: B125 | L11: HVACCP-206 | M11: 411001359644 | N11: Active | O11: Yes | P11: =CONCATENATE("IN-BLR-ANANTA-",C11,"_",J11) -> IN-BLR-ANANTA-DDC-207_B1 | Q11: uuid://2be1cc97-0df4-463e-8500-a803e1ecfe00 | R11: =IFS(C11="","",C11="n/a","N/A",LEN(C11),Concatenate("{",char(34),"asset",char(34),":{",char(34),"guid",char(34),":",char(34),Q11,char(34),",",char(34),"site",char(34),":",char(34),LOWER('2-Building'!$B$4),char(34),",",char(34),"name",char(34),":",char(34),LOWER(C11),char(34),"}}")) -> {"asset":{"guid":"uuid://2be1cc97-0df4-463e-8500-a803e1ecfe00","site":"in-blr-ananta","name":"ddc-207"}} | S11: Eneffen | V11: 2.23 | W11: V3.4 | X11: 5.0.1 | Y11: BACnet IP | Z11: 14007 | AA11: 11501 | AE11: Corphosted | AF11: 5C:C2:13:06:8D:86 | AG11: =IFS(LEN(AF11)=17,LOWER('2-Building'!$B$4 & "-" & C11), AF11="N/A", "N/A", LEN(AF11)=0,"") -> in-blr-ananta-ddc-207 | AK11: 100.95.214.228 | AL11: 255.255.240.0 | AM11: None | AR11: Primary | AS11: BACnet,47808 | AT11: DDC-2 | AU11: Unicast | AV11: No | AW11: N/A | AX11: Gateway Device | AY11: Good | AZ11: Eneffen | BA11: 10 | BB11: Yes | BD11: Landlord | BE11: Basebuilder System and connected on Gen Network | BF11: =IFERROR(__xludf.DUMMYFUNCTION("LOWER(Regexreplace(to_text(E11),""[^A-Za-z0-9]"","""")&""_""&Regexreplace(to_text(F11),""[^A-Za-z0-9]"",""""))"),"sauter_eyrc504fxxx") -> sauter_eyrc504fxxx | BG11: =IFERROR(__xludf.DUMMYFUNCTION("upper(Regexreplace(to_text(E11),""[^A-Za-z0-9]"","""")&""-""&Regexreplace(to_text(F11),""[^A-Za-z0-9]"",""""))"),"SAUTER-EYRC504FXXX") -> SAUTER-EYRC504FXXX
